<?xml version="1.0"?>
<robot name="multipleshapes">
   <material name="red">
        <color rgba="0 1 0.8 1"/>
    </material>  
    
    <material name="blue">
        <color rgba="1 0 0.8 1"/>
    </material> 
    
    <material name="green">
        <color rgba="1 1 0.8 1"/>
    </material> 
    
    <material name="m1">
        <color rgba="0.5 0.5 0.8 1"/>
    </material>
    
  <link name="base_link">
    <visual>
      <geometry>
         <box size="0.2 2 0.2"/>
      </geometry>
      <material name="blue"/>
    </visual>
  </link>

  <link name="slider_base">
    <visual>
      <geometry>
        <box size="0.2 0.2  1"/>
      </geometry>
      <material name="red"/>
    </visual>
  </link>
  
  <link name="slider">
    <visual>
      <geometry>
        <box size="0.2 0.1  1"/>
      </geometry>
      <material name="green"/>
    </visual>
  </link>
  
  <link name="hummer_hand">
    <visual>
      <geometry>
        <box size="0.2 0.2  2"/>
      </geometry>
      <material name="m1"/>
    </visual>
  </link>
  
  <link name="hummer">
    <visual>
      <geometry>
        <cylinder radius="0.2" length="0.5"/>
      </geometry>
      <material name="m1"/>
    </visual>
  </link>

  <joint name="base_to_slider" type="prismatic">
    <parent link="base_link"/>
    <child link="slider_base"/>
    <origin xyz="0 0 0.6"/>
    <axis xyz="0 1 0"/>
    <limit effort="1000.0" lower="-0.8" upper="0.8" velocity="0.5"/>
  </joint>
  
  <joint name="slide" type="prismatic">
    <parent link="slider_base"/>
    <child link="slider"/>
    <origin xyz="0 0.15 0"/>
    <axis xyz="0 0 1"/>
    <limit effort="1000.0" lower="0" upper="0.9" velocity="0.5"/>
  </joint>
  
  <joint name="rotate" type="continuous">
    <parent link="slider"/>
    <child link="hummer_hand"/>
    <origin xyz="0 0.15 0.5"/>
    <axis xyz="0 1 0"/>
  </joint>
  
  <joint name="fix" type="fixed">
    <parent link="hummer_hand"/>
    <child link="hummer"/>
    <origin rpy="0 1.57 0" xyz="0.2 0 1"/>
  </joint>
  
  

</robot>
